Workbook

Sheet Results
A2: Hong Seh 10-year fleet replacement and charging
A4: Fill Fleet register, Replacement plan, then Energy and charging. Inputs are amber. Horizon is fixed at 120 months.
A6: =IF('Operating costs'!$B$61="Demonstration","DEMONSTRATION. Not a customer savings claim.","Customer entry. Verify quotes, operations and source records.") -> DEMONSTRATION. Not a customer savings claim.
A8: Metric | B8: Keep ICE, then new ICE | C8: All-new ICE now | D8: Plan A | E8: Plan B
A9: Truck count | B9: =COUNTIFS(Paths!$B$7:$B$406,0,Paths!$C$7:$C$406,1) -> 6 | C9: =COUNTIFS(Paths!$B$7:$B$406,1,Paths!$C$7:$C$406,1) -> 6 | D9: =COUNTIFS(Paths!$B$7:$B$406,2,Paths!$C$7:$C$406,1) -> 6 | E9: =COUNTIFS(Paths!$B$7:$B$406,3,Paths!$C$7:$C$406,1) -> 6
A10: EVs at month 0 | B10: =COUNTIFS(Paths!$B$7:$B$406,0,Paths!$C$7:$C$406,1,Paths!$D$7:$D$406,"EV",Paths!$E$7:$E$406,0) -> 0 | C10: =COUNTIFS(Paths!$B$7:$B$406,1,Paths!$C$7:$C$406,1,Paths!$D$7:$D$406,"EV",Paths!$E$7:$E$406,0) -> 0 | D10: =COUNTIFS(Paths!$B$7:$B$406,2,Paths!$C$7:$C$406,1,Paths!$D$7:$D$406,"EV",Paths!$E$7:$E$406,0) -> 1 | E10: =COUNTIFS(Paths!$B$7:$B$406,3,Paths!$C$7:$C$406,1,Paths!$D$7:$D$406,"EV",Paths!$E$7:$E$406,0) -> 3
A11: EVs at year 10 | B11: =COUNTIFS(Paths!$B$7:$B$406,0,Paths!$C$7:$C$406,1,Paths!$D$7:$D$406,"EV",Paths!$E$7:$E$406,"<120") -> 0 | C11: =COUNTIFS(Paths!$B$7:$B$406,1,Paths!$C$7:$C$406,1,Paths!$D$7:$D$406,"EV",Paths!$E$7:$E$406,"<120") -> 0 | D11: =COUNTIFS(Paths!$B$7:$B$406,2,Paths!$C$7:$C$406,1,Paths!$D$7:$D$406,"EV",Paths!$E$7:$E$406,"<120") -> 1 | E11: =COUNTIFS(Paths!$B$7:$B$406,3,Paths!$C$7:$C$406,1,Paths!$D$7:$D$406,"EV",Paths!$E$7:$E$406,"<120") -> 3
A12: Vehicle economic TCO | B12: =IF(AND(COUNTIFS(Paths!$B$7:$B$406,0,Paths!$C$7:$C$406,1,Paths!$P$7:$P$406,"<>Complete")=0,COUNTIFS(Paths!$B$7:$B$406,0,Paths!$C$7:$C$406,1)=SUM('Fleet register'!$B$7:$B$106)),SUMIFS('Annual build'!$N$7:$N$4406,'Annual build'!$B$7:$B$4406,0),"n.a.") -> 2081781 | C12: =IF(AND(COUNTIFS(Paths!$B$7:$B$406,1,Paths!$C$7:$C$406,1,Paths!$P$7:$P$406,"<>Complete")=0,COUNTIFS(Paths!$B$7:$B$406,1,Paths!$C$7:$C$406,1)=SUM('Fleet register'!$B$7:$B$106)),SUMIFS('Annual build'!$N$7:$N$4406,'Annual build'!$B$7:$B$4406,1),"n.a.") -> 2103081 | D12: =IF(AND(COUNTIFS(Paths!$B$7:$B$406,2,Paths!$C$7:$C$406,1,Paths!$P$7:$P$406,"<>Complete")=0,COUNTIFS(Paths!$B$7:$B$406,2,Paths!$C$7:$C$406,1)=SUM('Fleet register'!$B$7:$B$106)),SUMIFS('Annual build'!$N$7:$N$4406,'Annual build'!$B$7:$B$4406,2),"n.a.") -> 2046736 | E12: =IF(AND(COUNTIFS(Paths!$B$7:$B$406,3,Paths!$C$7:$C$406,1,Paths!$P$7:$P$406,"<>Complete")=0,COUNTIFS(Paths!$B$7:$B$406,3,Paths!$C$7:$C$406,1)=SUM('Fleet register'!$B$7:$B$106)),SUMIFS('Annual build'!$N$7:$N$4406,'Annual build'!$B$7:$B$4406,3),"n.a.") -> 1986546
A13: Net site ownership cost | B13: =0 -> 0 | C13: =0 -> 0 | D13: =IF(COUNT(F45:F55)=11,SUM(F45:F55),"n.a.") -> n.a. | E13: =IF(COUNT(G45:G55)=11,SUM(G45:G55),"n.a.") -> n.a.
A14: Total economic TCO | B14: =IF(AND(ISNUMBER(B12),ISNUMBER(B13)),SUM(B12:B13),"n.a.") -> 2081781 | C14: =IF(AND(ISNUMBER(C12),ISNUMBER(C13)),SUM(C12:C13),"n.a.") -> 2103081 | D14: =IF(AND(ISNUMBER(D12),ISNUMBER(D13)),SUM(D12:D13),"n.a.") -> n.a. | E14: =IF(AND(ISNUMBER(E12),ISNUMBER(E13)),SUM(E12:E13),"n.a.") -> n.a.
A15: Saving vs Keep ICE | B15: =IF(AND(ISNUMBER(B14),ISNUMBER(B14)),B14-B14,"n.a.") -> 0 | C15: =IF(AND(ISNUMBER(B14),ISNUMBER(C14)),B14-C14,"n.a.") -> -21300 | D15: =IF(AND(ISNUMBER(B14),ISNUMBER(D14)),B14-D14,"n.a.") -> n.a. | E15: =IF(AND(ISNUMBER(B14),ISNUMBER(E14)),B14-E14,"n.a.") -> n.a.
A16: Saving percentage | B16: =IF(AND(ISNUMBER(B15),ISNUMBER(B14),B14>0),B15/B14,"n.a.") -> 0 | C16: =IF(AND(ISNUMBER(C15),ISNUMBER(B14),B14>0),C15/B14,"n.a.") -> -0.010231624 | D16: =IF(AND(ISNUMBER(D15),ISNUMBER(B14),B14>0),D15/B14,"n.a.") -> n.a. | E16: =IF(AND(ISNUMBER(E15),ISNUMBER(B14),B14>0),E15/B14,"n.a.") -> n.a.
A17: 15% fleet saving headroom | B17: =IF(AND(ISNUMBER(B14),ISNUMBER(B14)),0.85*B14-B14,"n.a.") -> -312267.15 | C17: =IF(AND(ISNUMBER(B14),ISNUMBER(C14)),0.85*B14-C14,"n.a.") -> -333567.15 | D17: =IF(AND(ISNUMBER(B14),ISNUMBER(D14)),0.85*B14-D14,"n.a.") -> n.a. | E17: =IF(AND(ISNUMBER(B14),ISNUMBER(E14)),0.85*B14-E14,"n.a.") -> n.a.
A18: Cash less year-10 assets | B18: =IF(COUNT(B45:B55)=11,SUM(B45:B55),"n.a.") -> 1847781 | C18: =IF(COUNT(C45:C55)=11,SUM(C45:C55),"n.a.") -> 1869081 | D18: =IF(COUNT(D45:D55)=11,SUM(D45:D55),"n.a.") -> n.a. | E18: =IF(COUNT(E45:E55)=11,SUM(E45:E55),"n.a.") -> n.a.
A19: Day-0 funding before loans | B19: =IF(AND(AND(COUNTIFS(Paths!$B$7:$B$406,0,Paths!$C$7:$C$406,1,Paths!$P$7:$P$406,"<>Complete")=0,COUNTIFS(Paths!$B$7:$B$406,0,Paths!$C$7:$C$406,1)=SUM('Fleet register'!$B$7:$B$106)),ISNUMBER(B45)),SUMIFS('Annual build'!$R$7:$R$4406,'Annual build'!$B$7:$B$4406,0),"n.a.") -> 0 | C19: =IF(AND(AND(COUNTIFS(Paths!$B$7:$B$406,1,Paths!$C$7:$C$406,1,Paths!$P$7:$P$406,"<>Complete")=0,COUNTIFS(Paths!$B$7:$B$406,1,Paths!$C$7:$C$406,1)=SUM('Fleet register'!$B$7:$B$106)),ISNUMBER(C45)),SUMIFS('Annual build'!$R$7:$R$4406,'Annual build'!$B$7:$B$4406,1),"n.a.") -> 852000 | D19: =IF(AND(AND(COUNTIFS(Paths!$B$7:$B$406,2,Paths!$C$7:$C$406,1,Paths!$P$7:$P$406,"<>Complete")=0,COUNTIFS(Paths!$B$7:$B$406,2,Paths!$C$7:$C$406,1)=SUM('Fleet register'!$B$7:$B$106)),ISNUMBER(D45)),SUMIFS('Annual build'!$R$7:$R$4406,'Annual build'!$B$7:$B$4406,2)+H45,"n.a.") -> n.a. | E19: =IF(AND(AND(COUNTIFS(Paths!$B$7:$B$406,3,Paths!$C$7:$C$406,1,Paths!$P$7:$P$406,"<>Complete")=0,COUNTIFS(Paths!$B$7:$B$406,3,Paths!$C$7:$C$406,1)=SUM('Fleet register'!$B$7:$B$106)),ISNUMBER(E45)),SUMIFS('Annual build'!$R$7:$R$4406,'Annual build'!$B$7:$B$4406,3)+I45,"n.a.") -> n.a.
A20: Incremental day-0 funding | B20: =IF(AND(ISNUMBER(B19),ISNUMBER(B19)),B19-B19,"n.a.") -> 0 | C20: =IF(AND(ISNUMBER(C19),ISNUMBER(B19)),C19-B19,"n.a.") -> 852000 | D20: =IF(AND(ISNUMBER(D19),ISNUMBER(B19)),D19-B19,"n.a.") -> n.a. | E20: =IF(AND(ISNUMBER(E19),ISNUMBER(B19)),E19-B19,"n.a.") -> n.a.
A21: Cost per productive km | B21: =IF(AND(ISNUMBER(B14),SUMIFS('Annual build'!$S$7:$S$4406,'Annual build'!$B$7:$B$4406,0)>0),B14/SUMIFS('Annual build'!$S$7:$S$4406,'Annual build'!$B$7:$B$4406,0),"n.a.") -> 0.77103 | C21: =IF(AND(ISNUMBER(C14),SUMIFS('Annual build'!$S$7:$S$4406,'Annual build'!$B$7:$B$4406,1)>0),C14/SUMIFS('Annual build'!$S$7:$S$4406,'Annual build'!$B$7:$B$4406,1),"n.a.") -> 0.77891889 | D21: =IF(AND(ISNUMBER(D14),SUMIFS('Annual build'!$S$7:$S$4406,'Annual build'!$B$7:$B$4406,2)>0),D14/SUMIFS('Annual build'!$S$7:$S$4406,'Annual build'!$B$7:$B$4406,2),"n.a.") -> n.a. | E21: =IF(AND(ISNUMBER(E14),SUMIFS('Annual build'!$S$7:$S$4406,'Annual build'!$B$7:$B$4406,3)>0),E14/SUMIFS('Annual build'!$S$7:$S$4406,'Annual build'!$B$7:$B$4406,3),"n.a.") -> n.a.
A22: Site completeness / access | B22: ="Not applicable" -> Not applicable | C22: ="Not applicable" -> Not applicable | D22: ='Energy and charging'!$B$67 -> Missing site quote | E22: ='Energy and charging'!$C$67 -> Missing site quote
A23: Vehicle service / evidence | B23: =IF(NOT(AND(COUNTIFS(Paths!$B$7:$B$406,0,Paths!$C$7:$C$406,1,Paths!$P$7:$P$406,"<>Complete")=0,COUNTIFS(Paths!$B$7:$B$406,0,Paths!$C$7:$C$406,1)=SUM('Fleet register'!$B$7:$B$106))),"Missing/invalid vehicle inputs",IF(COUNTIFS(Paths!$B$7:$B$406,0,Paths!$C$7:$C$406,1,Paths!$Q$7:$Q$406,"Fails entered limits")>0,"Fails entered limits",IF(COUNTIFS(Paths!$B$7:$B$406,0,Paths!$C$7:$C$406,1,Paths!$Q$7:$Q$406,"Unverified")>0,"Vehicle evidence open","Within entered limits"))) -> Within entered limits | C23: =IF(NOT(AND(COUNTIFS(Paths!$B$7:$B$406,1,Paths!$C$7:$C$406,1,Paths!$P$7:$P$406,"<>Complete")=0,COUNTIFS(Paths!$B$7:$B$406,1,Paths!$C$7:$C$406,1)=SUM('Fleet register'!$B$7:$B$106))),"Missing/invalid vehicle inputs",IF(COUNTIFS(Paths!$B$7:$B$406,1,Paths!$C$7:$C$406,1,Paths!$Q$7:$Q$406,"Fails entered limits")>0,"Fails entered limits",IF(COUNTIFS(Paths!$B$7:$B$406,1,Paths!$C$7:$C$406,1,Paths!$Q$7:$Q$406,"Unverified")>0,"Vehicle evidence open","Within entered limits"))) -> Within entered limits | D23: =IF(NOT(AND(COUNTIFS(Paths!$B$7:$B$406,2,Paths!$C$7:$C$406,1,Paths!$P$7:$P$406,"<>Complete")=0,COUNTIFS(Paths!$B$7:$B$406,2,Paths!$C$7:$C$406,1)=SUM('Fleet register'!$B$7:$B$106))),"Missing/invalid vehicle inputs",IF(COUNTIFS(Paths!$B$7:$B$406,2,Paths!$C$7:$C$406,1,Paths!$Q$7:$Q$406,"Fails entered limits")>0,"Fails entered limits",IF(COUNTIFS(Paths!$B$7:$B$406,2,Paths!$C$7:$C$406,1,Paths!$Q$7:$Q$406,"Unverified")>0,"Vehicle evidence open","Within entered limits"))) -> Fails entered limits | E23: =IF(NOT(AND(COUNTIFS(Paths!$B$7:$B$406,3,Paths!$C$7:$C$406,1,Paths!$P$7:$P$406,"<>Complete")=0,COUNTIFS(Paths!$B$7:$B$406,3,Paths!$C$7:$C$406,1)=SUM('Fleet register'!$B$7:$B$106))),"Missing/invalid vehicle inputs",IF(COUNTIFS(Paths!$B$7:$B$406,3,Paths!$C$7:$C$406,1,Paths!$Q$7:$Q$406,"Fails entered limits")>0,"Fails entered limits",IF(COUNTIFS(Paths!$B$7:$B$406,3,Paths!$C$7:$C$406,1,Paths!$Q$7:$Q$406,"Unverified")>0,"Vehicle evidence open","Within entered limits"))) -> Fails entered limits
A24: Saving claim status | B24: =IF(NOT(ISNUMBER(B14)),"Total incomplete",IF(OR(B9<=0,NOT(ISNUMBER(B16)),B23<>"Within entered limits",AND(0>=2,B11>0,NOT(OR(B22="Within entered site limits",B22="Public access entered"))),'Operating costs'!$B$61<>"Customer",'Operating costs'!$B$60<>"Yes",COUNTIFS('Fleet register'!$B$7:$B$106,1,'Fleet register'!$Q$7:$Q$106,"")>0,COUNTIFS(Paths!$B$7:$B$406,0,Paths!$C$7:$C$406,1,Paths!$AN$7:$AN$406,"<>Verified")>0),"Diagnostic only",IF(B16>=0.15,"Meets entered 15% target","Below entered 15% target"))) -> Diagnostic only | C24: =IF(NOT(ISNUMBER(C14)),"Total incomplete",IF(OR(C9<=0,NOT(ISNUMBER(C16)),C23<>"Within entered limits",AND(1>=2,C11>0,NOT(OR(C22="Within entered site limits",C22="Public access entered"))),'Operating costs'!$B$61<>"Customer",'Operating costs'!$B$60<>"Yes",COUNTIFS('Fleet register'!$B$7:$B$106,1,'Fleet register'!$Q$7:$Q$106,"")>0,COUNTIFS(Paths!$B$7:$B$406,1,Paths!$C$7:$C$406,1,Paths!$AN$7:$AN$406,"<>Verified")>0),"Diagnostic only",IF(C16>=0.15,"Meets entered 15% target","Below entered 15% target"))) -> Diagnostic only | D24: =IF(NOT(ISNUMBER(D14)),"Total incomplete",IF(OR(D9<=0,NOT(ISNUMBER(D16)),D23<>"Within entered limits",AND(2>=2,D11>0,NOT(OR(D22="Within entered site limits",D22="Public access entered"))),'Operating costs'!$B$61<>"Customer",'Operating costs'!$B$60<>"Yes",COUNTIFS('Fleet register'!$B$7:$B$106,1,'Fleet register'!$Q$7:$Q$106,"")>0,COUNTIFS(Paths!$B$7:$B$406,2,Paths!$C$7:$C$406,1,Paths!$AN$7:$AN$406,"<>Verified")>0),"Diagnostic only",IF(D16>=0.15,"Meets entered 15% target","Below entered 15% target"))) -> Total incomplete | E24: =IF(NOT(ISNUMBER(E14)),"Total incomplete",IF(OR(E9<=0,NOT(ISNUMBER(E16)),E23<>"Within entered limits",AND(3>=2,E11>0,NOT(OR(E22="Within entered site limits",E22="Public access entered"))),'Operating costs'!$B$61<>"Customer",'Operating costs'!$B$60<>"Yes",COUNTIFS('Fleet register'!$B$7:$B$106,1,'Fleet register'!$Q$7:$Q$106,"")>0,COUNTIFS(Paths!$B$7:$B$406,3,Paths!$C$7:$C$406,1,Paths!$AN$7:$AN$406,"<>Verified")>0),"Diagnostic only",IF(E16>=0.15,"Meets entered 15% target","Below entered 15% target"))) -> Total incomplete
A26: Max site TCO for 15% fleet saving | D26: =IF(AND(ISNUMBER(B14),ISNUMBER(D12)),0.85*B14-D12,"n.a.") -> -277222.17 | E26: =IF(AND(ISNUMBER(B14),ISNUMBER(E12)),0.85*B14-E12,"n.a.") -> -217032.2
A27: Commercial versus public rates (tariff-only, Plan A year-1 volume)
A28: Energy | B28: 100% commercial | C28: 100% public | D28: Entered blend
A29: ICE energy/year | B29: =SUMIFS(Paths!$AA$7:$AA$406,Paths!$B$7:$B$406,2,Paths!$C$7:$C$406,1)*'Energy and charging'!$B$7 -> 54273.6 | C29: =SUMIFS(Paths!$AA$7:$AA$406,Paths!$B$7:$B$406,2,Paths!$C$7:$C$406,1)*'Energy and charging'!$B$8 -> 81410.4 | D29: =SUMIFS(Paths!$AA$7:$AA$406,Paths!$B$7:$B$406,2,Paths!$C$7:$C$406,1)*('Energy and charging'!$B$9*'Energy and charging'!$B$7+(1-'Energy and charging'!$B$9)*'Energy and charging'!$B$8) -> 54273.6
A30: EV energy/year | B30: =SUMIFS(Paths!$X$7:$X$406,Paths!$B$7:$B$406,2,Paths!$C$7:$C$406,1,Paths!$D$7:$D$406,"EV")*'Energy and charging'!$B$10 -> 4741.8465 | C30: =SUMIFS(Paths!$X$7:$X$406,Paths!$B$7:$B$406,2,Paths!$C$7:$C$406,1,Paths!$D$7:$D$406,"EV")*'Energy and charging'!$B$11 -> 11588.757 | D30: =SUMIFS(Paths!$X$7:$X$406,Paths!$B$7:$B$406,2,Paths!$C$7:$C$406,1,Paths!$D$7:$D$406,"EV")*((1-'Energy and charging'!$B$12)*'Energy and charging'!$B$10+'Energy and charging'!$B$12*'Energy and charging'!$B$11) -> 6111.2286
A32: Tariff-only holds volumes fixed. Full plans change public-share detours, queues, paid time and installation costs.
A34: Additional day-0 budget | B34: ='Operating costs'!$B$55 -> 250000
A35: Budget headroom A / B | D35: =IF(ISNUMBER(D20),'Operating costs'!$B$55-MAX(0,D20),"n.a.") -> n.a. | E35: =IF(ISNUMBER(E20),'Operating costs'!$B$55-MAX(0,E20),"n.a.") -> n.a.
A37: To compare 1 EV with 1 ICE: include only that truck, or inspect vehicle-only cost and quote a standalone charging plan.
A39: No confirmed installation total yet. Equipment prices and site-rent schedules are benchmarks, not complete projects.
A41: Cash excludes financing. Refundable deposits affect cash, not full economic cost. Future residual values are forecasts.
A42: EV servicing uses the selected model's Hong Seh 200,000 km average unless Annual override is selected. The average smooths service timing.
A44: Year | B44: Keep ICE cash less assets | C44: New ICE cash less assets | D44: Plan A cash less assets | E44: Plan B cash less assets | F44: A site economic | G44: B site economic | H44: A site cash | I44: B site cash
A45: 0 | B45: =IF(AND(COUNTIFS(Paths!$B$7:$B$406,0,Paths!$C$7:$C$406,1,Paths!$P$7:$P$406,"<>Complete")=0,COUNTIFS(Paths!$B$7:$B$406,0,Paths!$C$7:$C$406,1)=SUM('Fleet register'!$B$7:$B$106)),SUMIFS('Annual build'!$O$7:$O$4406,'Annual build'!$B$7:$B$4406,0,'Annual build'!$C$7:$C$4406,$A45),"n.a.") -> 0 | C45: =IF(AND(COUNTIFS(Paths!$B$7:$B$406,1,Paths!$C$7:$C$406,1,Paths!$P$7:$P$406,"<>Complete")=0,COUNTIFS(Paths!$B$7:$B$406,1,Paths!$C$7:$C$406,1)=SUM('Fleet register'!$B$7:$B$106)),SUMIFS('Annual build'!$O$7:$O$4406,'Annual build'!$B$7:$B$4406,1,'Annual build'!$C$7:$C$4406,$A45),"n.a.") -> 852000 | D45: =IF(AND(COUNTIFS(Paths!$B$7:$B$406,2,Paths!$C$7:$C$406,1,Paths!$P$7:$P$406,"<>Complete")=0,COUNTIFS(Paths!$B$7:$B$406,2,Paths!$C$7:$C$406,1)=SUM('Fleet register'!$B$7:$B$106)),IF(ISNUMBER(H45),SUMIFS('Annual build'!$O$7:$O$4406,'Annual build'!$B$7:$B$4406,2,'Annual build'!$C$7:$C$4406,$A45)+H45,"n.a."),"n.a.") -> n.a. | E45: =IF(AND(COUNTIFS(Paths!$B$7:$B$406,3,Paths!$C$7:$C$406,1,Paths!$P$7:$P$406,"<>Complete")=0,COUNTIFS(Paths!$B$7:$B$406,3,Paths!$C$7:$C$406,1)=SUM('Fleet register'!$B$7:$B$106)),IF(ISNUMBER(I45),SUMIFS('Annual build'!$O$7:$O$4406,'Annual build'!$B$7:$B$4406,3,'Annual build'!$C$7:$C$4406,$A45)+I45,"n.a."),"n.a.") -> n.a. | F45: =IF('Energy and charging'!$B$60="No EV site",0,IF('Energy and charging'!$B$60="Public only",IF(IF('Energy and charging'!$B$33=0,$A45=0,AND($A45>0,'Energy and charging'!$B$33>($A45-1)*12,'Energy and charging'!$B$33<=$A45*12)),'Energy and charging'!$B$27,0)+0/12*'Energy and charging'!$B$29*(1+'Operating costs'!$B$53)^MAX(0,$A45-1),IF('Energy and charging'!$B$60="Complete",IF(IF('Energy and charging'!$B$33=0,$A45=0,AND($A45>0,'Energy and charging'!$B$33>($A45-1)*12,'Energy and charging'!$B$33<=$A45*12)),'Energy and charging'!$B$61,0)+0/12*'Energy and charging'!$B$62*(1+'Operating costs'!$B$53)^MAX(0,$A45-1)-IF(IF('Energy and charging'!$B$45=0,$A45=0,AND($A45>0,'Energy and charging'!$B$45>($A45-1)*12,'Energy and charging'!$B$45<=$A45*12)),'Energy and charging'!$B$44,0)+IF(IF('Energy and charging'!$B$38=0,$A45=0,AND($A45>0,'Energy and charging'!$B$38>($A45-1)*12,'Energy and charging'!$B$38<=$A45*12)),'Energy and charging'!$B$37,0)+IF(IF('Energy and charging'!$B$41=0,$A45=0,AND($A45>0,'Energy and charging'!$B$41>($A45-1)*12,'Energy and charging'!$B$41<=$A45*12)),'Energy and charging'!$B$16*'Energy and charging'!$B$40,0)+IF(IF('Energy and charging'!$B$33+'Energy and charging'!$B$34=0,$A45=0,AND($A45>0,'Energy and charging'!$B$33+'Energy and charging'!$B$34>($A45-1)*12,'Energy and charging'!$B$33+'Energy and charging'!$B$34<=$A45*12)),'Energy and charging'!$B$36,0)-IF($A45=10,'Energy and charging'!$B$35,0),"n.a."))) -> n.a. | G45: =IF('Energy and charging'!$C$60="No EV site",0,IF('Energy and charging'!$C$60="Public only",IF(IF('Energy and charging'!$C$33=0,$A45=0,AND($A45>0,'Energy and charging'!$C$33>($A45-1)*12,'Energy and charging'!$C$33<=$A45*12)),'Energy and charging'!$C$27,0)+0/12*'Energy and charging'!$C$29*(1+'Operating costs'!$B$53)^MAX(0,$A45-1),IF('Energy and charging'!$C$60="Complete",IF(IF('Energy and charging'!$C$33=0,$A45=0,AND($A45>0,'Energy and charging'!$C$33>($A45-1)*12,'Energy and charging'!$C$33<=$A45*12)),'Energy and charging'!$C$61,0)+0/12*'Energy and charging'!$C$62*(1+'Operating costs'!$B$53)^MAX(0,$A45-1)-IF(IF('Energy and charging'!$C$45=0,$A45=0,AND($A45>0,'Energy and charging'!$C$45>($A45-1)*12,'Energy and charging'!$C$45<=$A45*12)),'Energy and charging'!$C$44,0)+IF(IF('Energy and charging'!$C$38=0,$A45=0,AND($A45>0,'Energy and charging'!$C$38>($A45-1)*12,'Energy and charging'!$C$38<=$A45*12)),'Energy and charging'!$C$37,0)+IF(IF('Energy and charging'!$C$41=0,$A45=0,AND($A45>0,'Energy and charging'!$C$41>($A45-1)*12,'Energy and charging'!$C$41<=$A45*12)),'Energy and charging'!$C$16*'Energy and charging'!$C$40,0)+IF(IF('Energy and charging'!$C$33+'Energy and charging'!$C$34=0,$A45=0,AND($A45>0,'Energy and charging'!$C$33+'Energy and charging'!$C$34>($A45-1)*12,'Energy and charging'!$C$33+'Energy and charging'!$C$34<=$A45*12)),'Energy and charging'!$C$36,0)-IF($A45=10,'Energy and charging'!$C$35,0),"n.a."))) -> n.a. | H45: =IF(ISNUMBER(F45),F45+IF(AND('Energy and charging'!$B$60="Complete",IF('Energy and charging'!$B$33=0,$A45=0,AND($A45>0,'Energy and charging'!$B$33>($A45-1)*12,'Energy and charging'!$B$33<=$A45*12))),'Energy and charging'!$B$42,0)-IF(AND('Energy and charging'!$B$60="Complete",IF('Energy and charging'!$B$43=0,$A45=0,AND($A45>0,'Energy and charging'!$B$43>($A45-1)*12,'Energy and charging'!$B$43<=$A45*12))),'Energy and charging'!$B$42,0),"n.a.") -> n.a. | I45: =IF(ISNUMBER(G45),G45+IF(AND('Energy and charging'!$C$60="Complete",IF('Energy and charging'!$C$33=0,$A45=0,AND($A45>0,'Energy and charging'!$C$33>($A45-1)*12,'Energy and charging'!$C$33<=$A45*12))),'Energy and charging'!$C$42,0)-IF(AND('Energy and charging'!$C$60="Complete",IF('Energy and charging'!$C$43=0,$A45=0,AND($A45>0,'Energy and charging'!$C$43>($A45-1)*12,'Energy and charging'!$C$43<=$A45*12))),'Energy and charging'!$C$42,0),"n.a.") -> n.a.
A46: 1 | B46: =IF(AND(COUNTIFS(Paths!$B$7:$B$406,0,Paths!$C$7:$C$406,1,Paths!$P$7:$P$406,"<>Complete")=0,COUNTIFS(Paths!$B$7:$B$406,0,Paths!$C$7:$C$406,1)=SUM('Fleet register'!$B$7:$B$106)),SUMIFS('Annual build'!$O$7:$O$4406,'Annual build'!$B$7:$B$4406,0,'Annual build'!$C$7:$C$4406,$A46),"n.a.") -> 279908.1 | C46: =IF(AND(COUNTIFS(Paths!$B$7:$B$406,1,Paths!$C$7:$C$406,1,Paths!$P$7:$P$406,"<>Complete")=0,COUNTIFS(Paths!$B$7:$B$406,1,Paths!$C$7:$C$406,1)=SUM('Fleet register'!$B$7:$B$106)),SUMIFS('Annual build'!$O$7:$O$4406,'Annual build'!$B$7:$B$4406,1,'Annual build'!$C$7:$C$4406,$A46),"n.a.") -> 108908.1 | D46: =IF(AND(COUNTIFS(Paths!$B$7:$B$406,2,Paths!$C$7:$C$406,1,Paths!$P$7:$P$406,"<>Complete")=0,COUNTIFS(Paths!$B$7:$B$406,2,Paths!$C$7:$C$406,1)=SUM('Fleet register'!$B$7:$B$106)),IF(ISNUMBER(H46),SUMIFS('Annual build'!$O$7:$O$4406,'Annual build'!$B$7:$B$4406,2,'Annual build'!$C$7:$C$4406,$A46)+H46,"n.a."),"n.a.") -> n.a. | E46: =IF(AND(COUNTIFS(Paths!$B$7:$B$406,3,Paths!$C$7:$C$406,1,Paths!$P$7:$P$406,"<>Complete")=0,COUNTIFS(Paths!$B$7:$B$406,3,Paths!$C$7:$C$406,1)=SUM('Fleet register'!$B$7:$B$106)),IF(ISNUMBER(I46),SUMIFS('Annual build'!$O$7:$O$4406,'Annual build'!$B$7:$B$4406,3,'Annual build'!$C$7:$C$4406,$A46)+I46,"n.a."),"n.a.") -> n.a. | F46: =IF('Energy and charging'!$B$60="No EV site",0,IF('Energy and charging'!$B$60="Public only",IF(IF('Energy and charging'!$B$33=0,$A46=0,AND($A46>0,'Energy and charging'!$B$33>($A46-1)*12,'Energy and charging'!$B$33<=$A46*12)),'Energy and charging'!$B$27,0)+MAX(0,MIN(1*12,120)-MAX(0,'Energy and charging'!$B$33))/12*'Energy and charging'!$B$29*(1+'Operating costs'!$B$53)^MAX(0,$A46-1),IF('Energy and charging'!$B$60="Complete",IF(IF('Energy and charging'!$B$33=0,$A46=0,AND($A46>0,'Energy and charging'!$B$33>($A46-1)*12,'Energy and charging'!$B$33<=$A46*12)),'Energy and charging'!$B$61,0)+MAX(0,MIN(1*12,120)-MAX(0,'Energy and charging'!$B$33))/12*'Energy and charging'!$B$62*(1+'Operating costs'!$B$53)^MAX(0,$A46-1)-IF(IF('Energy and charging'!$B$45=0,$A46=0,AND($A46>0,'Energy and charging'!$B$45>($A46-1)*12,'Energy and charging'!$B$45<=$A46*12)),'Energy and charging'!$B$44,0)+IF(IF('Energy and charging'!$B$38=0,$A46=0,AND($A46>0,'Energy and charging'!$B$38>($A46-1)*12,'Energy and charging'!$B$38<=$A46*12)),'Energy and charging'!$B$37,0)+IF(IF('Energy and charging'!$B$41=0,$A46=0,AND($A46>0,'Energy and charging'!$B$41>($A46-1)*12,'Energy and charging'!$B$41<=$A46*12)),'Energy and charging'!$B$16*'Energy and charging'!$B$40,0)+IF(IF('Energy and charging'!$B$33+'Energy and charging'!$B$34=0,$A46=0,AND($A46>0,'Energy and charging'!$B$33+'Energy and charging'!$B$34>($A46-1)*12,'Energy and charging'!$B$33+'Energy and charging'!$B$34<=$A46*12)),'Energy and charging'!$B$36,0)-IF($A46=10,'Energy and charging'!$B$35,0),"n.a."))) -> n.a. | G46: =IF('Energy and charging'!$C$60="No EV site",0,IF('Energy and charging'!$C$60="Public only",IF(IF('Energy and charging'!$C$33=0,$A46=0,AND($A46>0,'Energy and charging'!$C$33>($A46-1)*12,'Energy and charging'!$C$33<=$A46*12)),'Energy and charging'!$C$27,0)+MAX(0,MIN(1*12,120)-MAX(0,'Energy and charging'!$C$33))/12*'Energy and charging'!$C$29*(1+'Operating costs'!$B$53)^MAX(0,$A46-1),IF('Energy and charging'!$C$60="Complete",IF(IF('Energy and charging'!$C$33=0,$A46=0,AND($A46>0,'Energy and charging'!$C$33>($A46-1)*12,'Energy and charging'!$C$33<=$A46*12)),'Energy and charging'!$C$61,0)+MAX(0,MIN(1*12,120)-MAX(0,'Energy and charging'!$C$33))/12*'Energy and charging'!$C$62*(1+'Operating costs'!$B$53)^MAX(0,$A46-1)-IF(IF('Energy and charging'!$C$45=0,$A46=0,AND($A46>0,'Energy and charging'!$C$45>($A46-1)*12,'Energy and charging'!$C$45<=$A46*12)),'Energy and charging'!$C$44,0)+IF(IF('Energy and charging'!$C$38=0,$A46=0,AND($A46>0,'Energy and charging'!$C$38>($A46-1)*12,'Energy and charging'!$C$38<=$A46*12)),'Energy and charging'!$C$37,0)+IF(IF('Energy and charging'!$C$41=0,$A46=0,AND($A46>0,'Energy and charging'!$C$41>($A46-1)*12,'Energy and charging'!$C$41<=$A46*12)),'Energy and charging'!$C$16*'Energy and charging'!$C$40,0)+IF(IF('Energy and charging'!$C$33+'Energy and charging'!$C$34=0,$A46=0,AND($A46>0,'Energy and charging'!$C$33+'Energy and charging'!$C$34>($A46-1)*12,'Energy and charging'!$C$33+'Energy and charging'!$C$34<=$A46*12)),'Energy and charging'!$C$36,0)-IF($A46=10,'Energy and charging'!$C$35,0),"n.a."))) -> n.a. | H46: =IF(ISNUMBER(F46),F46+IF(AND('Energy and charging'!$B$60="Complete",IF('Energy and charging'!$B$33=0,$A46=0,AND($A46>0,'Energy and charging'!$B$33>($A46-1)*12,'Energy and charging'!$B$33<=$A46*12))),'Energy and charging'!$B$42,0)-IF(AND('Energy and charging'!$B$60="Complete",IF('Energy and charging'!$B$43=0,$A46=0,AND($A46>0,'Energy and charging'!$B$43>($A46-1)*12,'Energy and charging'!$B$43<=$A46*12))),'Energy and charging'!$B$42,0),"n.a.") -> n.a. | I46: =IF(ISNUMBER(G46),G46+IF(AND('Energy and charging'!$C$60="Complete",IF('Energy and charging'!$C$33=0,$A46=0,AND($A46>0,'Energy and charging'!$C$33>($A46-1)*12,'Energy and charging'!$C$33<=$A46*12))),'Energy and charging'!$C$42,0)-IF(AND('Energy and charging'!$C$60="Complete",IF('Energy and charging'!$C$43=0,$A46=0,AND($A46>0,'Energy and charging'!$C$43>($A46-1)*12,'Energy and charging'!$C$43<=$A46*12))),'Energy and charging'!$C$42,0),"n.a.") -> n.a.
A47: 2 | B47: =IF(AND(COUNTIFS(Paths!$B$7:$B$406,0,Paths!$C$7:$C$406,1,Paths!$P$7:$P$406,"<>Complete")=0,COUNTIFS(Paths!$B$7:$B$406,0,Paths!$C$7:$C$406,1)=SUM('Fleet register'!$B$7:$B$106)),SUMIFS('Annual build'!$O$7:$O$4406,'Annual build'!$B$7:$B$4406,0,'Annual build'!$C$7:$C$4406,$A47),"n.a.") -> 279908.1 | C47: =IF(AND(COUNTIFS(Paths!$B$7:$B$406,1,Paths!$C$7:$C$406,1,Paths!$P$7:$P$406,"<>Complete")=0,COUNTIFS(Paths!$B$7:$B$406,1,Paths!$C$7:$C$406,1)=SUM('Fleet register'!$B$7:$B$106)),SUMIFS('Annual build'!$O$7:$O$4406,'Annual build'!$B$7:$B$4406,1,'Annual build'!$C$7:$C$4406,$A47),"n.a.") -> 108908.1 | D47: =IF(AND(COUNTIFS(Paths!$B$7:$B$406,2,Paths!$C$7:$C$406,1,Paths!$P$7:$P$406,"<>Complete")=0,COUNTIFS(Paths!$B$7:$B$406,2,Paths!$C$7:$C$406,1)=SUM('Fleet register'!$B$7:$B$106)),IF(ISNUMBER(H47),SUMIFS('Annual build'!$O$7:$O$4406,'Annual build'!$B$7:$B$4406,2,'Annual build'!$C$7:$C$4406,$A47)+H47,"n.a."),"n.a.") -> n.a. | E47: =IF(AND(COUNTIFS(Paths!$B$7:$B$406,3,Paths!$C$7:$C$406,1,Paths!$P$7:$P$406,"<>Complete")=0,COUNTIFS(Paths!$B$7:$B$406,3,Paths!$C$7:$C$406,1)=SUM('Fleet register'!$B$7:$B$106)),IF(ISNUMBER(I47),SUMIFS('Annual build'!$O$7:$O$4406,'Annual build'!$B$7:$B$4406,3,'Annual build'!$C$7:$C$4406,$A47)+I47,"n.a."),"n.a.") -> n.a. | F47: =IF('Energy and charging'!$B$60="No EV site",0,IF('Energy and charging'!$B$60="Public only",IF(IF('Energy and charging'!$B$33=0,$A47=0,AND($A47>0,'Energy and charging'!$B$33>($A47-1)*12,'Energy and charging'!$B$33<=$A47*12)),'Energy and charging'!$B$27,0)+MAX(0,MIN(2*12,120)-MAX(12,'Energy and charging'!$B$33))/12*'Energy and charging'!$B$29*(1+'Operating costs'!$B$53)^MAX(0,$A47-1),IF('Energy and charging'!$B$60="Complete",IF(IF('Energy and charging'!$B$33=0,$A47=0,AND($A47>0,'Energy and charging'!$B$33>($A47-1)*12,'Energy and charging'!$B$33<=$A47*12)),'Energy and charging'!$B$61,0)+MAX(0,MIN(2*12,120)-MAX(12,'Energy and charging'!$B$33))/12*'Energy and charging'!$B$62*(1+'Operating costs'!$B$53)^MAX(0,$A47-1)-IF(IF('Energy and charging'!$B$45=0,$A47=0,AND($A47>0,'Energy and charging'!$B$45>($A47-1)*12,'Energy and charging'!$B$45<=$A47*12)),'Energy and charging'!$B$44,0)+IF(IF('Energy and charging'!$B$38=0,$A47=0,AND($A47>0,'Energy and charging'!$B$38>($A47-1)*12,'Energy and charging'!$B$38<=$A47*12)),'Energy and charging'!$B$37,0)+IF(IF('Energy and charging'!$B$41=0,$A47=0,AND($A47>0,'Energy and charging'!$B$41>($A47-1)*12,'Energy and charging'!$B$41<=$A47*12)),'Energy and charging'!$B$16*'Energy and charging'!$B$40,0)+IF(IF('Energy and charging'!$B$33+'Energy and charging'!$B$34=0,$A47=0,AND($A47>0,'Energy and charging'!$B$33+'Energy and charging'!$B$34>($A47-1)*12,'Energy and charging'!$B$33+'Energy and charging'!$B$34<=$A47*12)),'Energy and charging'!$B$36,0)-IF($A47=10,'Energy and charging'!$B$35,0),"n.a."))) -> n.a. | G47: =IF('Energy and charging'!$C$60="No EV site",0,IF('Energy and charging'!$C$60="Public only",IF(IF('Energy and charging'!$C$33=0,$A47=0,AND($A47>0,'Energy and charging'!$C$33>($A47-1)*12,'Energy and charging'!$C$33<=$A47*12)),'Energy and charging'!$C$27,0)+MAX(0,MIN(2*12,120)-MAX(12,'Energy and charging'!$C$33))/12*'Energy and charging'!$C$29*(1+'Operating costs'!$B$53)^MAX(0,$A47-1),IF('Energy and charging'!$C$60="Complete",IF(IF('Energy and charging'!$C$33=0,$A47=0,AND($A47>0,'Energy and charging'!$C$33>($A47-1)*12,'Energy and charging'!$C$33<=$A47*12)),'Energy and charging'!$C$61,0)+MAX(0,MIN(2*12,120)-MAX(12,'Energy and charging'!$C$33))/12*'Energy and charging'!$C$62*(1+'Operating costs'!$B$53)^MAX(0,$A47-1)-IF(IF('Energy and charging'!$C$45=0,$A47=0,AND($A47>0,'Energy and charging'!$C$45>($A47-1)*12,'Energy and charging'!$C$45<=$A47*12)),'Energy and charging'!$C$44,0)+IF(IF('Energy and charging'!$C$38=0,$A47=0,AND($A47>0,'Energy and charging'!$C$38>($A47-1)*12,'Energy and charging'!$C$38<=$A47*12)),'Energy and charging'!$C$37,0)+IF(IF('Energy and charging'!$C$41=0,$A47=0,AND($A47>0,'Energy and charging'!$C$41>($A47-1)*12,'Energy and charging'!$C$41<=$A47*12)),'Energy and charging'!$C$16*'Energy and charging'!$C$40,0)+IF(IF('Energy and charging'!$C$33+'Energy and charging'!$C$34=0,$A47=0,AND($A47>0,'Energy and charging'!$C$33+'Energy and charging'!$C$34>($A47-1)*12,'Energy and charging'!$C$33+'Energy and charging'!$C$34<=$A47*12)),'Energy and charging'!$C$36,0)-IF($A47=10,'Energy and charging'!$C$35,0),"n.a."))) -> n.a. | H47: =IF(ISNUMBER(F47),F47+IF(AND('Energy and charging'!$B$60="Complete",IF('Energy and charging'!$B$33=0,$A47=0,AND($A47>0,'Energy and charging'!$B$33>($A47-1)*12,'Energy and charging'!$B$33<=$A47*12))),'Energy and charging'!$B$42,0)-IF(AND('Energy and charging'!$B$60="Complete",IF('Energy and charging'!$B$43=0,$A47=0,AND($A47>0,'Energy and charging'!$B$43>($A47-1)*12,'Energy and charging'!$B$43<=$A47*12))),'Energy and charging'!$B$42,0),"n.a.") -> n.a. | I47: =IF(ISNUMBER(G47),G47+IF(AND('Energy and charging'!$C$60="Complete",IF('Energy and charging'!$C$33=0,$A47=0,AND($A47>0,'Energy and charging'!$C$33>($A47-1)*12,'Energy and charging'!$C$33<=$A47*12))),'Energy and charging'!$C$42,0)-IF(AND('Energy and charging'!$C$60="Complete",IF('Energy and charging'!$C$43=0,$A47=0,AND($A47>0,'Energy and charging'!$C$43>($A47-1)*12,'Energy and charging'!$C$43<=$A47*12))),'Energy and charging'!$C$42,0),"n.a.") -> n.a.
A48: 3 | B48: =IF(AND(COUNTIFS(Paths!$B$7:$B$406,0,Paths!$C$7:$C$406,1,Paths!$P$7:$P$406,"<>Complete")=0,COUNTIFS(Paths!$B$7:$B$406,0,Paths!$C$7:$C$406,1)=SUM('Fleet register'!$B$7:$B$106)),SUMIFS('Annual build'!$O$7:$O$4406,'Annual build'!$B$7:$B$4406,0,'Annual build'!$C$7:$C$4406,$A48),"n.a.") -> 279908.1 | C48: =IF(AND(COUNTIFS(Paths!$B$7:$B$406,1,Paths!$C$7:$C$406,1,Paths!$P$7:$P$406,"<>Complete")=0,COUNTIFS(Paths!$B$7:$B$406,1,Paths!$C$7:$C$406,1)=SUM('Fleet register'!$B$7:$B$106)),SUMIFS('Annual build'!$O$7:$O$4406,'Annual build'!$B$7:$B$4406,1,'Annual build'!$C$7:$C$4406,$A48),"n.a.") -> 108908.1 | D48: =IF(AND(COUNTIFS(Paths!$B$7:$B$406,2,Paths!$C$7:$C$406,1,Paths!$P$7:$P$406,"<>Complete")=0,COUNTIFS(Paths!$B$7:$B$406,2,Paths!$C$7:$C$406,1)=SUM('Fleet register'!$B$7:$B$106)),IF(ISNUMBER(H48),SUMIFS('Annual build'!$O$7:$O$4406,'Annual build'!$B$7:$B$4406,2,'Annual build'!$C$7:$C$4406,$A48)+H48,"n.a."),"n.a.") -> n.a. | E48: =IF(AND(COUNTIFS(Paths!$B$7:$B$406,3,Paths!$C$7:$C$406,1,Paths!$P$7:$P$406,"<>Complete")=0,COUNTIFS(Paths!$B$7:$B$406,3,Paths!$C$7:$C$406,1)=SUM('Fleet register'!$B$7:$B$106)),IF(ISNUMBER(I48),SUMIFS('Annual build'!$O$7:$O$4406,'Annual build'!$B$7:$B$4406,3,'Annual build'!$C$7:$C$4406,$A48)+I48,"n.a."),"n.a.") -> n.a. | F48: =IF('Energy and charging'!$B$60="No EV site",0,IF('Energy and charging'!$B$60="Public only",IF(IF('Energy and charging'!$B$33=0,$A48=0,AND($A48>0,'Energy and charging'!$B$33>($A48-1)*12,'Energy and charging'!$B$33<=$A48*12)),'Energy and charging'!$B$27,0)+MAX(0,MIN(3*12,120)-MAX(24,'Energy and charging'!$B$33))/12*'Energy and charging'!$B$29*(1+'Operating costs'!$B$53)^MAX(0,$A48-1),IF('Energy and charging'!$B$60="Complete",IF(IF('Energy and charging'!$B$33=0,$A48=0,AND($A48>0,'Energy and charging'!$B$33>($A48-1)*12,'Energy and charging'!$B$33<=$A48*12)),'Energy and charging'!$B$61,0)+MAX(0,MIN(3*12,120)-MAX(24,'Energy and charging'!$B$33))/12*'Energy and charging'!$B$62*(1+'Operating costs'!$B$53)^MAX(0,$A48-1)-IF(IF('Energy and charging'!$B$45=0,$A48=0,AND($A48>0,'Energy and charging'!$B$45>($A48-1)*12,'Energy and charging'!$B$45<=$A48*12)),'Energy and charging'!$B$44,0)+IF(IF('Energy and charging'!$B$38=0,$A48=0,AND($A48>0,'Energy and charging'!$B$38>($A48-1)*12,'Energy and charging'!$B$38<=$A48*12)),'Energy and charging'!$B$37,0)+IF(IF('Energy and charging'!$B$41=0,$A48=0,AND($A48>0,'Energy and charging'!$B$41>($A48-1)*12,'Energy and charging'!$B$41<=$A48*12)),'Energy and charging'!$B$16*'Energy and charging'!$B$40,0)+IF(IF('Energy and charging'!$B$33+'Energy and charging'!$B$34=0,$A48=0,AND($A48>0,'Energy and charging'!$B$33+'Energy and charging'!$B$34>($A48-1)*12,'Energy and charging'!$B$33+'Energy and charging'!$B$34<=$A48*12)),'Energy and charging'!$B$36,0)-IF($A48=10,'Energy and charging'!$B$35,0),"n.a."))) -> n.a. | G48: =IF('Energy and charging'!$C$60="No EV site",0,IF('Energy and charging'!$C$60="Public only",IF(IF('Energy and charging'!$C$33=0,$A48=0,AND($A48>0,'Energy and charging'!$C$33>($A48-1)*12,'Energy and charging'!$C$33<=$A48*12)),'Energy and charging'!$C$27,0)+MAX(0,MIN(3*12,120)-MAX(24,'Energy and charging'!$C$33))/12*'Energy and charging'!$C$29*(1+'Operating costs'!$B$53)^MAX(0,$A48-1),IF('Energy and charging'!$C$60="Complete",IF(IF('Energy and charging'!$C$33=0,$A48=0,AND($A48>0,'Energy and charging'!$C$33>($A48-1)*12,'Energy and charging'!$C$33<=$A48*12)),'Energy and charging'!$C$61,0)+MAX(0,MIN(3*12,120)-MAX(24,'Energy and charging'!$C$33))/12*'Energy and charging'!$C$62*(1+'Operating costs'!$B$53)^MAX(0,$A48-1)-IF(IF('Energy and charging'!$C$45=0,$A48=0,AND($A48>0,'Energy and charging'!$C$45>($A48-1)*12,'Energy and charging'!$C$45<=$A48*12)),'Energy and charging'!$C$44,0)+IF(IF('Energy and charging'!$C$38=0,$A48=0,AND($A48>0,'Energy and charging'!$C$38>($A48-1)*12,'Energy and charging'!$C$38<=$A48*12)),'Energy and charging'!$C$37,0)+IF(IF('Energy and charging'!$C$41=0,$A48=0,AND($A48>0,'Energy and charging'!$C$41>($A48-1)*12,'Energy and charging'!$C$41<=$A48*12)),'Energy and charging'!$C$16*'Energy and charging'!$C$40,0)+IF(IF('Energy and charging'!$C$33+'Energy and charging'!$C$34=0,$A48=0,AND($A48>0,'Energy and charging'!$C$33+'Energy and charging'!$C$34>($A48-1)*12,'Energy and charging'!$C$33+'Energy and charging'!$C$34<=$A48*12)),'Energy and charging'!$C$36,0)-IF($A48=10,'Energy and charging'!$C$35,0),"n.a."))) -> n.a. | H48: =IF(ISNUMBER(F48),F48+IF(AND('Energy and charging'!$B$60="Complete",IF('Energy and charging'!$B$33=0,$A48=0,AND($A48>0,'Energy and charging'!$B$33>($A48-1)*12,'Energy and charging'!$B$33<=$A48*12))),'Energy and charging'!$B$42,0)-IF(AND('Energy and charging'!$B$60="Complete",IF('Energy and charging'!$B$43=0,$A48=0,AND($A48>0,'Energy and charging'!$B$43>($A48-1)*12,'Energy and charging'!$B$43<=$A48*12))),'Energy and charging'!$B$42,0),"n.a.") -> n.a. | I48: =IF(ISNUMBER(G48),G48+IF(AND('Energy and charging'!$C$60="Complete",IF('Energy and charging'!$C$33=0,$A48=0,AND($A48>0,'Energy and charging'!$C$33>($A48-1)*12,'Energy and charging'!$C$33<=$A48*12))),'Energy and charging'!$C$42,0)-IF(AND('Energy and charging'!$C$60="Complete",IF('Energy and charging'!$C$43=0,$A48=0,AND($A48>0,'Energy and charging'!$C$43>($A48-1)*12,'Energy and charging'!$C$43<=$A48*12))),'Energy and charging'!$C$42,0),"n.a.") -> n.a.
A49: 4 | B49: =IF(AND(COUNTIFS(Paths!$B$7:$B$406,0,Paths!$C$7:$C$406,1,Paths!$P$7:$P$406,"<>Complete")=0,COUNTIFS(Paths!$B$7:$B$406,0,Paths!$C$7:$C$406,1)=SUM('Fleet register'!$B$7:$B$106)),SUMIFS('Annual build'!$O$7:$O$4406,'Annual build'!$B$7:$B$4406,0,'Annual build'!$C$7:$C$4406,$A49),"n.a.") -> 279908.1 | C49: =IF(AND(COUNTIFS(Paths!$B$7:$B$406,1,Paths!$C$7:$C$406,1,Paths!$P$7:$P$406,"<>Complete")=0,COUNTIFS(Paths!$B$7:$B$406,1,Paths!$C$7:$C$406,1)=SUM('Fleet register'!$B$7:$B$106)),SUMIFS('Annual build'!$O$7:$O$4406,'Annual build'!$B$7:$B$4406,1,'Annual build'!$C$7:$C$4406,$A49),"n.a.") -> 108908.1 | D49: =IF(AND(COUNTIFS(Paths!$B$7:$B$406,2,Paths!$C$7:$C$406,1,Paths!$P$7:$P$406,"<>Complete")=0,COUNTIFS(Paths!$B$7:$B$406,2,Paths!$C$7:$C$406,1)=SUM('Fleet register'!$B$7:$B$106)),IF(ISNUMBER(H49),SUMIFS('Annual build'!$O$7:$O$4406,'Annual build'!$B$7:$B$4406,2,'Annual build'!$C$7:$C$4406,$A49)+H49,"n.a."),"n.a.") -> n.a. | E49: =IF(AND(COUNTIFS(Paths!$B$7:$B$406,3,Paths!$C$7:$C$406,1,Paths!$P$7:$P$406,"<>Complete")=0,COUNTIFS(Paths!$B$7:$B$406,3,Paths!$C$7:$C$406,1)=SUM('Fleet register'!$B$7:$B$106)),IF(ISNUMBER(I49),SUMIFS('Annual build'!$O$7:$O$4406,'Annual build'!$B$7:$B$4406,3,'Annual build'!$C$7:$C$4406,$A49)+I49,"n.a."),"n.a.") -> n.a. | F49: =IF('Energy and charging'!$B$60="No EV site",0,IF('Energy and charging'!$B$60="Public only",IF(IF('Energy and charging'!$B$33=0,$A49=0,AND($A49>0,'Energy and charging'!$B$33>($A49-1)*12,'Energy and charging'!$B$33<=$A49*12)),'Energy and charging'!$B$27,0)+MAX(0,MIN(4*12,120)-MAX(36,'Energy and charging'!$B$33))/12*'Energy and charging'!$B$29*(1+'Operating costs'!$B$53)^MAX(0,$A49-1),IF('Energy and charging'!$B$60="Complete",IF(IF('Energy and charging'!$B$33=0,$A49=0,AND($A49>0,'Energy and charging'!$B$33>($A49-1)*12,'Energy and charging'!$B$33<=$A49*12)),'Energy and charging'!$B$61,0)+MAX(0,MIN(4*12,120)-MAX(36,'Energy and charging'!$B$33))/12*'Energy and charging'!$B$62*(1+'Operating costs'!$B$53)^MAX(0,$A49-1)-IF(IF('Energy and charging'!$B$45=0,$A49=0,AND($A49>0,'Energy and charging'!$B$45>($A49-1)*12,'Energy and charging'!$B$45<=$A49*12)),'Energy and charging'!$B$44,0)+IF(IF('Energy and charging'!$B$38=0,$A49=0,AND($A49>0,'Energy and charging'!$B$38>($A49-1)*12,'Energy and charging'!$B$38<=$A49*12)),'Energy and charging'!$B$37,0)+IF(IF('Energy and charging'!$B$41=0,$A49=0,AND($A49>0,'Energy and charging'!$B$41>($A49-1)*12,'Energy and charging'!$B$41<=$A49*12)),'Energy and charging'!$B$16*'Energy and charging'!$B$40,0)+IF(IF('Energy and charging'!$B$33+'Energy and charging'!$B$34=0,$A49=0,AND($A49>0,'Energy and charging'!$B$33+'Energy and charging'!$B$34>($A49-1)*12,'Energy and charging'!$B$33+'Energy and charging'!$B$34<=$A49*12)),'Energy and charging'!$B$36,0)-IF($A49=10,'Energy and charging'!$B$35,0),"n.a."))) -> n.a. | G49: =IF('Energy and charging'!$C$60="No EV site",0,IF('Energy and charging'!$C$60="Public only",IF(IF('Energy and charging'!$C$33=0,$A49=0,AND($A49>0,'Energy and charging'!$C$33>($A49-1)*12,'Energy and charging'!$C$33<=$A49*12)),'Energy and charging'!$C$27,0)+MAX(0,MIN(4*12,120)-MAX(36,'Energy and charging'!$C$33))/12*'Energy and charging'!$C$29*(1+'Operating costs'!$B$53)^MAX(0,$A49-1),IF('Energy and charging'!$C$60="Complete",IF(IF('Energy and charging'!$C$33=0,$A49=0,AND($A49>0,'Energy and charging'!$C$33>($A49-1)*12,'Energy and charging'!$C$33<=$A49*12)),'Energy and charging'!$C$61,0)+MAX(0,MIN(4*12,120)-MAX(36,'Energy and charging'!$C$33))/12*'Energy and charging'!$C$62*(1+'Operating costs'!$B$53)^MAX(0,$A49-1)-IF(IF('Energy and charging'!$C$45=0,$A49=0,AND($A49>0,'Energy and charging'!$C$45>($A49-1)*12,'Energy and charging'!$C$45<=$A49*12)),'Energy and charging'!$C$44,0)+IF(IF('Energy and charging'!$C$38=0,$A49=0,AND($A49>0,'Energy and charging'!$C$38>($A49-1)*12,'Energy and charging'!$C$38<=$A49*12)),'Energy and charging'!$C$37,0)+IF(IF('Energy and charging'!$C$41=0,$A49=0,AND($A49>0,'Energy and charging'!$C$41>($A49-1)*12,'Energy and charging'!$C$41<=$A49*12)),'Energy and charging'!$C$16*'Energy and charging'!$C$40,0)+IF(IF('Energy and charging'!$C$33+'Energy and charging'!$C$34=0,$A49=0,AND($A49>0,'Energy and charging'!$C$33+'Energy and charging'!$C$34>($A49-1)*12,'Energy and charging'!$C$33+'Energy and charging'!$C$34<=$A49*12)),'Energy and charging'!$C$36,0)-IF($A49=10,'Energy and charging'!$C$35,0),"n.a."))) -> n.a. | H49: =IF(ISNUMBER(F49),F49+IF(AND('Energy and charging'!$B$60="Complete",IF('Energy and charging'!$B$33=0,$A49=0,AND($A49>0,'Energy and charging'!$B$33>($A49-1)*12,'Energy and charging'!$B$33<=$A49*12))),'Energy and charging'!$B$42,0)-IF(AND('Energy and charging'!$B$60="Complete",IF('Energy and charging'!$B$43=0,$A49=0,AND($A49>0,'Energy and charging'!$B$43>($A49-1)*12,'Energy and charging'!$B$43<=$A49*12))),'Energy and charging'!$B$42,0),"n.a.") -> n.a. | I49: =IF(ISNUMBER(G49),G49+IF(AND('Energy and charging'!$C$60="Complete",IF('Energy and charging'!$C$33=0,$A49=0,AND($A49>0,'Energy and charging'!$C$33>($A49-1)*12,'Energy and charging'!$C$33<=$A49*12))),'Energy and charging'!$C$42,0)-IF(AND('Energy and charging'!$C$60="Complete",IF('Energy and charging'!$C$43=0,$A49=0,AND($A49>0,'Energy and charging'!$C$43>($A49-1)*12,'Energy and charging'!$C$43<=$A49*12))),'Energy and charging'!$C$42,0),"n.a.") -> n.a.
A50: 5 | B50: =IF(AND(COUNTIFS(Paths!$B$7:$B$406,0,Paths!$C$7:$C$406,1,Paths!$P$7:$P$406,"<>Complete")=0,COUNTIFS(Paths!$B$7:$B$406,0,Paths!$C$7:$C$406,1)=SUM('Fleet register'!$B$7:$B$106)),SUMIFS('Annual build'!$O$7:$O$4406,'Annual build'!$B$7:$B$4406,0,'Annual build'!$C$7:$C$4406,$A50),"n.a.") -> 279908.1 | C50: =IF(AND(COUNTIFS(Paths!$B$7:$B$406,1,Paths!$C$7:$C$406,1,Paths!$P$7:$P$406,"<>Complete")=0,COUNTIFS(Paths!$B$7:$B$406,1,Paths!$C$7:$C$406,1)=SUM('Fleet register'!$B$7:$B$106)),SUMIFS('Annual build'!$O$7:$O$4406,'Annual build'!$B$7:$B$4406,1,'Annual build'!$C$7:$C$4406,$A50),"n.a.") -> 108908.1 | D50: =IF(AND(COUNTIFS(Paths!$B$7:$B$406,2,Paths!$C$7:$C$406,1,Paths!$P$7:$P$406,"<>Complete")=0,COUNTIFS(Paths!$B$7:$B$406,2,Paths!$C$7:$C$406,1)=SUM('Fleet register'!$B$7:$B$106)),IF(ISNUMBER(H50),SUMIFS('Annual build'!$O$7:$O$4406,'Annual build'!$B$7:$B$4406,2,'Annual build'!$C$7:$C$4406,$A50)+H50,"n.a."),"n.a.") -> n.a. | E50: =IF(AND(COUNTIFS(Paths!$B$7:$B$406,3,Paths!$C$7:$C$406,1,Paths!$P$7:$P$406,"<>Complete")=0,COUNTIFS(Paths!$B$7:$B$406,3,Paths!$C$7:$C$406,1)=SUM('Fleet register'!$B$7:$B$106)),IF(ISNUMBER(I50),SUMIFS('Annual build'!$O$7:$O$4406,'Annual build'!$B$7:$B$4406,3,'Annual build'!$C$7:$C$4406,$A50)+I50,"n.a."),"n.a.") -> n.a. | F50: =IF('Energy and charging'!$B$60="No EV site",0,IF('Energy and charging'!$B$60="Public only",IF(IF('Energy and charging'!$B$33=0,$A50=0,AND($A50>0,'Energy and charging'!$B$33>($A50-1)*12,'Energy and charging'!$B$33<=$A50*12)),'Energy and charging'!$B$27,0)+MAX(0,MIN(5*12,120)-MAX(48,'Energy and charging'!$B$33))/12*'Energy and charging'!$B$29*(1+'Operating costs'!$B$53)^MAX(0,$A50-1),IF('Energy and charging'!$B$60="Complete",IF(IF('Energy and charging'!$B$33=0,$A50=0,AND($A50>0,'Energy and charging'!$B$33>($A50-1)*12,'Energy and charging'!$B$33<=$A50*12)),'Energy and charging'!$B$61,0)+MAX(0,MIN(5*12,120)-MAX(48,'Energy and charging'!$B$33))/12*'Energy and charging'!$B$62*(1+'Operating costs'!$B$53)^MAX(0,$A50-1)-IF(IF('Energy and charging'!$B$45=0,$A50=0,AND($A50>0,'Energy and charging'!$B$45>($A50-1)*12,'Energy and charging'!$B$45<=$A50*12)),'Energy and charging'!$B$44,0)+IF(IF('Energy and charging'!$B$38=0,$A50=0,AND($A50>0,'Energy and charging'!$B$38>($A50-1)*12,'Energy and charging'!$B$38<=$A50*12)),'Energy and charging'!$B$37,0)+IF(IF('Energy and charging'!$B$41=0,$A50=0,AND($A50>0,'Energy and charging'!$B$41>($A50-1)*12,'Energy and charging'!$B$41<=$A50*12)),'Energy and charging'!$B$16*'Energy and charging'!$B$40,0)+IF(IF('Energy and charging'!$B$33+'Energy and charging'!$B$34=0,$A50=0,AND($A50>0,'Energy and charging'!$B$33+'Energy and charging'!$B$34>($A50-1)*12,'Energy and charging'!$B$33+'Energy and charging'!$B$34<=$A50*12)),'Energy and charging'!$B$36,0)-IF($A50=10,'Energy and charging'!$B$35,0),"n.a."))) -> n.a. | G50: =IF('Energy and charging'!$C$60="No EV site",0,IF('Energy and charging'!$C$60="Public only",IF(IF('Energy and charging'!$C$33=0,$A50=0,AND($A50>0,'Energy and charging'!$C$33>($A50-1)*12,'Energy and charging'!$C$33<=$A50*12)),'Energy and charging'!$C$27,0)+MAX(0,MIN(5*12,120)-MAX(48,'Energy and charging'!$C$33))/12*'Energy and charging'!$C$29*(1+'Operating costs'!$B$53)^MAX(0,$A50-1),IF('Energy and charging'!$C$60="Complete",IF(IF('Energy and charging'!$C$33=0,$A50=0,AND($A50>0,'Energy and charging'!$C$33>($A50-1)*12,'Energy and charging'!$C$33<=$A50*12)),'Energy and charging'!$C$61,0)+MAX(0,MIN(5*12,120)-MAX(48,'Energy and charging'!$C$33))/12*'Energy and charging'!$C$62*(1+'Operating costs'!$B$53)^MAX(0,$A50-1)-IF(IF('Energy and charging'!$C$45=0,$A50=0,AND($A50>0,'Energy and charging'!$C$45>($A50-1)*12,'Energy and charging'!$C$45<=$A50*12)),'Energy and charging'!$C$44,0)+IF(IF('Energy and charging'!$C$38=0,$A50=0,AND($A50>0,'Energy and charging'!$C$38>($A50-1)*12,'Energy and charging'!$C$38<=$A50*12)),'Energy and charging'!$C$37,0)+IF(IF('Energy and charging'!$C$41=0,$A50=0,AND($A50>0,'Energy and charging'!$C$41>($A50-1)*12,'Energy and charging'!$C$41<=$A50*12)),'Energy and charging'!$C$16*'Energy and charging'!$C$40,0)+IF(IF('Energy and charging'!$C$33+'Energy and charging'!$C$34=0,$A50=0,AND($A50>0,'Energy and charging'!$C$33+'Energy and charging'!$C$34>($A50-1)*12,'Energy and charging'!$C$33+'Energy and charging'!$C$34<=$A50*12)),'Energy and charging'!$C$36,0)-IF($A50=10,'Energy and charging'!$C$35,0),"n.a."))) -> n.a. | H50: =IF(ISNUMBER(F50),F50+IF(AND('Energy and charging'!$B$60="Complete",IF('Energy and charging'!$B$33=0,$A50=0,AND($A50>0,'Energy and charging'!$B$33>($A50-1)*12,'Energy and charging'!$B$33<=$A50*12))),'Energy and charging'!$B$42,0)-IF(AND('Energy and charging'!$B$60="Complete",IF('Energy and charging'!$B$43=0,$A50=0,AND($A50>0,'Energy and charging'!$B$43>($A50-1)*12,'Energy and charging'!$B$43<=$A50*12))),'Energy and charging'!$B$42,0),"n.a.") -> n.a. | I50: =IF(ISNUMBER(G50),G50+IF(AND('Energy and charging'!$C$60="Complete",IF('Energy and charging'!$C$33=0,$A50=0,AND($A50>0,'Energy and charging'!$C$33>($A50-1)*12,'Energy and charging'!$C$33<=$A50*12))),'Energy and charging'!$C$42,0)-IF(AND('Energy and charging'!$C$60="Complete",IF('Energy and charging'!$C$43=0,$A50=0,AND($A50>0,'Energy and charging'!$C$43>($A50-1)*12,'Energy and charging'!$C$43<=$A50*12))),'Energy and charging'!$C$42,0),"n.a.") -> n.a.
A51: 6 | B51: =IF(AND(COUNTIFS(Paths!$B$7:$B$406,0,Paths!$C$7:$C$406,1,Paths!$P$7:$P$406,"<>Complete")=0,COUNTIFS(Paths!$B$7:$B$406,0,Paths!$C$7:$C$406,1)=SUM('Fleet register'!$B$7:$B$106)),SUMIFS('Annual build'!$O$7:$O$4406,'Annual build'!$B$7:$B$4406,0,'Annual build'!$C$7:$C$4406,$A51),"n.a.") -> 279908.1 | C51: =IF(AND(COUNTIFS(Paths!$B$7:$B$406,1,Paths!$C$7:$C$406,1,Paths!$P$7:$P$406,"<>Complete")=0,COUNTIFS(Paths!$B$7:$B$406,1,Paths!$C$7:$C$406,1)=SUM('Fleet register'!$B$7:$B$106)),SUMIFS('Annual build'!$O$7:$O$4406,'Annual build'!$B$7:$B$4406,1,'Annual build'!$C$7:$C$4406,$A51),"n.a.") -> 108908.1 | D51: =IF(AND(COUNTIFS(Paths!$B$7:$B$406,2,Paths!$C$7:$C$406,1,Paths!$P$7:$P$406,"<>Complete")=0,COUNTIFS(Paths!$B$7:$B$406,2,Paths!$C$7:$C$406,1)=SUM('Fleet register'!$B$7:$B$106)),IF(ISNUMBER(H51),SUMIFS('Annual build'!$O$7:$O$4406,'Annual build'!$B$7:$B$4406,2,'Annual build'!$C$7:$C$4406,$A51)+H51,"n.a."),"n.a.") -> n.a. | E51: =IF(AND(COUNTIFS(Paths!$B$7:$B$406,3,Paths!$C$7:$C$406,1,Paths!$P$7:$P$406,"<>Complete")=0,COUNTIFS(Paths!$B$7:$B$406,3,Paths!$C$7:$C$406,1)=SUM('Fleet register'!$B$7:$B$106)),IF(ISNUMBER(I51),SUMIFS('Annual build'!$O$7:$O$4406,'Annual build'!$B$7:$B$4406,3,'Annual build'!$C$7:$C$4406,$A51)+I51,"n.a."),"n.a.") -> n.a. | F51: =IF('Energy and charging'!$B$60="No EV site",0,IF('Energy and charging'!$B$60="Public only",IF(IF('Energy and charging'!$B$33=0,$A51=0,AND($A51>0,'Energy and charging'!$B$33>($A51-1)*12,'Energy and charging'!$B$33<=$A51*12)),'Energy and charging'!$B$27,0)+MAX(0,MIN(6*12,120)-MAX(60,'Energy and charging'!$B$33))/12*'Energy and charging'!$B$29*(1+'Operating costs'!$B$53)^MAX(0,$A51-1),IF('Energy and charging'!$B$60="Complete",IF(IF('Energy and charging'!$B$33=0,$A51=0,AND($A51>0,'Energy and charging'!$B$33>($A51-1)*12,'Energy and charging'!$B$33<=$A51*12)),'Energy and charging'!$B$61,0)+MAX(0,MIN(6*12,120)-MAX(60,'Energy and charging'!$B$33))/12*'Energy and charging'!$B$62*(1+'Operating costs'!$B$53)^MAX(0,$A51-1)-IF(IF('Energy and charging'!$B$45=0,$A51=0,AND($A51>0,'Energy and charging'!$B$45>($A51-1)*12,'Energy and charging'!$B$45<=$A51*12)),'Energy and charging'!$B$44,0)+IF(IF('Energy and charging'!$B$38=0,$A51=0,AND($A51>0,'Energy and charging'!$B$38>($A51-1)*12,'Energy and charging'!$B$38<=$A51*12)),'Energy and charging'!$B$37,0)+IF(IF('Energy and charging'!$B$41=0,$A51=0,AND($A51>0,'Energy and charging'!$B$41>($A51-1)*12,'Energy and charging'!$B$41<=$A51*12)),'Energy and charging'!$B$16*'Energy and charging'!$B$40,0)+IF(IF('Energy and charging'!$B$33+'Energy and charging'!$B$34=0,$A51=0,AND($A51>0,'Energy and charging'!$B$33+'Energy and charging'!$B$34>($A51-1)*12,'Energy and charging'!$B$33+'Energy and charging'!$B$34<=$A51*12)),'Energy and charging'!$B$36,0)-IF($A51=10,'Energy and charging'!$B$35,0),"n.a."))) -> n.a. | G51: =IF('Energy and charging'!$C$60="No EV site",0,IF('Energy and charging'!$C$60="Public only",IF(IF('Energy and charging'!$C$33=0,$A51=0,AND($A51>0,'Energy and charging'!$C$33>($A51-1)*12,'Energy and charging'!$C$33<=$A51*12)),'Energy and charging'!$C$27,0)+MAX(0,MIN(6*12,120)-MAX(60,'Energy and charging'!$C$33))/12*'Energy and charging'!$C$29*(1+'Operating costs'!$B$53)^MAX(0,$A51-1),IF('Energy and charging'!$C$60="Complete",IF(IF('Energy and charging'!$C$33=0,$A51=0,AND($A51>0,'Energy and charging'!$C$33>($A51-1)*12,'Energy and charging'!$C$33<=$A51*12)),'Energy and charging'!$C$61,0)+MAX(0,MIN(6*12,120)-MAX(60,'Energy and charging'!$C$33))/12*'Energy and charging'!$C$62*(1+'Operating costs'!$B$53)^MAX(0,$A51-1)-IF(IF('Energy and charging'!$C$45=0,$A51=0,AND($A51>0,'Energy and charging'!$C$45>($A51-1)*12,'Energy and charging'!$C$45<=$A51*12)),'Energy and charging'!$C$44,0)+IF(IF('Energy and charging'!$C$38=0,$A51=0,AND($A51>0,'Energy and charging'!$C$38>($A51-1)*12,'Energy and charging'!$C$38<=$A51*12)),'Energy and charging'!$C$37,0)+IF(IF('Energy and charging'!$C$41=0,$A51=0,AND($A51>0,'Energy and charging'!$C$41>($A51-1)*12,'Energy and charging'!$C$41<=$A51*12)),'Energy and charging'!$C$16*'Energy and charging'!$C$40,0)+IF(IF('Energy and charging'!$C$33+'Energy and charging'!$C$34=0,$A51=0,AND($A51>0,'Energy and charging'!$C$33+'Energy and charging'!$C$34>($A51-1)*12,'Energy and charging'!$C$33+'Energy and charging'!$C$34<=$A51*12)),'Energy and charging'!$C$36,0)-IF($A51=10,'Energy and charging'!$C$35,0),"n.a."))) -> n.a. | H51: =IF(ISNUMBER(F51),F51+IF(AND('Energy and charging'!$B$60="Complete",IF('Energy and charging'!$B$33=0,$A51=0,AND($A51>0,'Energy and charging'!$B$33>($A51-1)*12,'Energy and charging'!$B$33<=$A51*12))),'Energy and charging'!$B$42,0)-IF(AND('Energy and charging'!$B$60="Complete",IF('Energy and charging'!$B$43=0,$A51=0,AND($A51>0,'Energy and charging'!$B$43>($A51-1)*12,'Energy and charging'!$B$43<=$A51*12))),'Energy and charging'!$B$42,0),"n.a.") -> n.a. | I51: =IF(ISNUMBER(G51),G51+IF(AND('Energy and charging'!$C$60="Complete",IF('Energy and charging'!$C$33=0,$A51=0,AND($A51>0,'Energy and charging'!$C$33>($A51-1)*12,'Energy and charging'!$C$33<=$A51*12))),'Energy and charging'!$C$42,0)-IF(AND('Energy and charging'!$C$60="Complete",IF('Energy and charging'!$C$43=0,$A51=0,AND($A51>0,'Energy and charging'!$C$43>($A51-1)*12,'Energy and charging'!$C$43<=$A51*12))),'Energy and charging'!$C$42,0),"n.a.") -> n.a.
...

Sheet Fleet register
A2: 1. Enter each current truck and its work
A4: Include 1 = in this comparison. Up to 100 trucks. IDs must be unique. One duty is preserved in every plan.
A6: Truck ID | B6: Include 0/1 | C6: Duty / route | D6: Body | E6: Work km/day | F6: Days/year | G6: Peak route km | H6: Peak cargo kg | I6: Jobs/day | J6: COE months left | K6: Market value now | L6: Physical scrap | M6: COE paid basis | N6: COE term months | O6: Debt if sold now | P6: Fee when old truck sold | Q6: Evidence reference | R6: Vehicle age years | S6: Registration date
A7: T001 | B7: 1 | C7: Ambient demo | D7: Box | E7: 150 | F7: 300 | G7: 165 | H7: 1200 | I7: 24 | J7: 12 | K7: 24000 | L7: 10000 | M7: 60000 | N7: 120 | O7: 0 | P7: 0 | Q7: DEMO-1 | R7: 9
A8: T002 | B8: 1 | C8: Ambient demo | D8: Box | E8: 150 | F8: 300 | G8: 165 | H8: 1200 | I8: 24 | J8: 24 | K8: 30000 | L8: 10000 | M8: 60000 | N8: 120 | O8: 0 | P8: 0 | Q8: DEMO-2 | R8: 8
A9: T003 | B9: 1 | C9: Ambient demo | D9: Box | E9: 150 | F9: 300 | G9: 165 | H9: 1200 | I9: 24 | J9: 36 | K9: 36000 | L9: 10000 | M9: 60000 | N9: 120 | O9: 0 | P9: 0 | Q9: DEMO-3 | R9: 7
A10: T004 | B10: 1 | C10: Ambient demo | D10: Box | E10: 150 | F10: 300 | G10: 165 | H10: 1200 | I10: 24 | J10: 48 | K10: 42000 | L10: 10000 | M10: 60000 | N10: 120 | O10: 0 | P10: 0 | Q10: DEMO-4 | R10: 6
A11: T005 | B11: 1 | C11: Ambient demo | D11: Box | E11: 150 | F11: 300 | G11: 165 | H11: 1200 | I11: 24 | J11: 60 | K11: 48000 | L11: 10000 | M11: 60000 | N11: 120 | O11: 0 | P11: 0 | Q11: DEMO-5 | R11: 5
A12: T006 | B12: 1 | C12: Ambient demo | D12: Box | E12: 150 | F12: 300 | G12: 165 | H12: 1200 | I12: 24 | J12: 72 | K12: 54000 | L12: 10000 | M12: 60000 | N12: 120 | O12: 0 | P12: 0 | Q12: DEMO-6 | R12: 4
A13: T007 | B13: 0
A14: T008 | B14: 0
A15: T009 | B15: 0
A16: T010 | B16: 0
A17: T011 | B17: 0
A18: T012 | B18: 0
A19: T013 | B19: 0
A20: T014 | B20: 0
A21: T015 | B21: 0
A22: T016 | B22: 0
A23: T017 | B23: 0
A24: T018 | B24: 0
... A106: T100 | B106: 0

Sheet Replacement plan
A2: 2. Set replacements, quotes and future values
A4: Keep ICE = retire at expiry or earlier entered month, then buy ICE. New ICE / EV = replace at chosen month.
A6: Truck ID | B6: EV model | C6: New ICE all-in quote | D6: EV all-in override | E6: Usable battery kWh | F6: EV kWh/km override | G6: Energy basis | H6: Approved payload kg | I6: Body fits EV | J6: Depot average kW | K6: Depot AC/DC | L6: Public average kW | M6: Keep retire override | N6: Keep terminal at year 10 | O6: Plan A action | P6: A month override | Q6: A year-10 value | R6: Plan B action | S6: B month override | T6: B year-10 value | U6: A gross disposal override | V6: B gross disposal override | W6: Old ICE extra /year | X6: New ICE extra /year | Y6: EV extra /year | Z6: Manual EV grant total | AA6: Grant offset months | AB6: Grant eligibility checked | AC6: EV life months | AD6: ICE life months | AE6: Quote / value evidence | AF6: Record reference | AG6: Old ICE litres/km override | AH6: New ICE litres/km override | AI6: All-new ICE now year-10 value override
A7: T001 | B7: ChengLong L2EV | C7: 181000 | G7: Battery | I7: Unconfirmed | J7: 22 | K7: DC | L7: 48 | N7: 21300 | O7: EV | P7: 0 | Q7: 8000 | R7: EV | S7: 0 | T7: 8000 | W7: 0 | X7: 0 | Y7: 0 | Z7: 0 | AA7: 0 | AB7: No | AC7: 120 | AD7: 120 | AE7: Assumed | AF7: DEMO-1
A8: T002 | B8: ChengLong L2EV | C8: 181000 | G8: Battery | I8: Unconfirmed | J8: 22 | K8: DC | L8: 48 | N8: 30600 | O8: Keep ICE | Q8: 30600 | R8: EV | S8: 0 | T8: 8000 | W8: 0 | X8: 0 | Y8: 0 | Z8: 0 | AA8: 0 | AB8: No | AC8: 120 | AD8: 120 | AE8: Assumed | AF8: DEMO-2
A9: T003 | B9: ChengLong L2EV | C9: 181000 | G9: Battery | I9: Unconfirmed | J9: 22 | K9: DC | L9: 48 | N9: 39900 | O9: Keep ICE | Q9: 39900 | R9: EV | S9: 0 | T9: 8000 | W9: 0 | X9: 0 | Y9: 0 | Z9: 0 | AA9: 0 | AB9: No | AC9: 120 | AD9: 120 | AE9: Assumed | AF9: DEMO-3
A10: T004 | B10: ChengLong L2EV | C10: 181000 | G10: Battery | I10: Unconfirmed | J10: 22 | K10: DC | L10: 48 | N10: 49200 | O10: Keep ICE | Q10: 49200 | R10: Keep ICE | T10: 49200 | W10: 0 | X10: 0 | Y10: 0 | Z10: 0 | AA10: 0 | AB10: No | AC10: 120 | AD10: 120 | AE10: Assumed | AF10: DEMO-4
A11: T005 | B11: ChengLong L2EV | C11: 181000 | G11: Battery | I11: Unconfirmed | J11: 22 | K11: DC | L11: 48 | N11: 58500 | O11: Keep ICE | Q11: 58500 | R11: Keep ICE | T11: 58500 | W11: 0 | X11: 0 | Y11: 0 | Z11: 0 | AA11: 0 | AB11: No | AC11: 120 | AD11: 120 | AE11: Assumed | AF11: DEMO-5
A12: T006 | B12: ChengLong L2EV | C12: 181000 | G12: Battery | I12: Unconfirmed | J12: 22 | K12: DC | L12: 48 | N12: 67800 | O12: Keep ICE | Q12: 67800 | R12: Keep ICE | T12: 67800 | W12: 0 | X12: 0 | Y12: 0 | Z12: 0 | AA12: 0 | AB12: No | AC12: 120 | AD12: 120 | AE12: Assumed | AF12: DEMO-6
A13: T007 | B13: ChengLong L2EV | C13: 181000 | G13: Battery | I13: Unconfirmed | J13: 22 | K13: DC | L13: 48 | O13: Keep ICE | R13: Keep ICE | W13: 0 | X13: 0 | Y13: 0 | Z13: 0 | AA13: 0 | AB13: No | AC13: 120 | AD13: 120 | AE13: Assumed
A14: T008 | B14: ChengLong L2EV | C14: 181000 | G14: Battery | I14: Unconfirmed | J14: 22 | K14: DC | L14: 48 | O14: Keep ICE | R14: Keep ICE | W14: 0 | X14: 0 | Y14: 0 | Z14: 0 | AA14: 0 | AB14: No | AC14: 120 | AD14: 120 | AE14: Assumed
A15: T009 | B15: ChengLong L2EV | C15: 181000 | G15: Battery | I15: Unconfirmed | J15: 22 | K15: DC | L15: 48 | O15: Keep ICE | R15: Keep ICE | W15: 0 | X15: 0 | Y15: 0 | Z15: 0 | AA15: 0 | AB15: No | AC15: 120 | AD15: 120 | AE15: Assumed
A16: T010 | B16: ChengLong L2EV | C16: 181000 | G16: Battery | I16: Unconfirmed | J16: 22 | K16: DC | L16: 48 | O16: Keep ICE | R16: Keep ICE | W16: 0 | X16: 0 | Y16: 0 | Z16: 0 | AA16: 0 | AB16: No | AC16: 120 | AD16: 120 | AE16: Assumed
A17: T011 | B17: ChengLong L2EV | C17: 181000 | G17: Battery | I17: Unconfirmed | J17: 22 | K17: DC | L17: 48 | O17: Keep ICE | R17: Keep ICE | W17: 0 | X17: 0 | Y17: 0 | Z17: 0 | AA17: 0 | AB17: No | AC17: 120 | AD17: 120 | AE17: Assumed
A18: T012 | B18: ChengLong L2EV | C18: 181000 | G18: Battery | I18: Unconfirmed | J18: 22 | K18: DC | L18: 48 | O18: Keep ICE | R18: Keep ICE | W18: 0 | X18: 0 | Y18: 0 | Z18: 0 | AA18: 0 | AB18: No | AC18: 120 | AD18: 120 | AE18: Assumed
A19: T013 | B19: ChengLong L2EV | C19: 181000 | G19: Battery | I19: Unconfirmed | J19: 22 | K19: DC | L19: 48 | O19: Keep ICE | R19: Keep ICE | W19: 0 | X19: 0 | Y19: 0 | Z19: 0 | AA19: 0 | AB19: No | AC19: 120 | AD19: 120 | AE19: Assumed
A20: T014 | B20: ChengLong L2EV | C20: 181000 | G20: Battery | I20: Unconfirmed | J20: 22 | K20: DC | L20: 48 | O20: Keep ICE | R20: Keep ICE | W20: 0 | X20: 0 | Y20: 0 | Z20: 0 | AA20: 0 | AB20: No | AC20: 120 | AD20: 120 | AE20: Assumed
A21: T015 | B21: ChengLong L2EV | C21: 181000 | G21: Battery | I21: Unconfirmed | J21: 22 | K21: DC | L21: 48 | O21: Keep ICE | R21: Keep ICE | W21: 0 | X21: 0 | Y21: 0 | Z21: 0 | AA21: 0 | AB21: No | AC21: 120 | AD21: 120 | AE21: Assumed
A22: T016 | B22: ChengLong L2EV | C22: 181000 | G22: Battery | I22: Unconfirmed | J22: 22 | K22: DC | L22: 48 | O22: Keep ICE | R22: Keep ICE | W22: 0 | X22: 0 | Y22: 0 | Z22: 0 | AA22: 0 | AB22: No | AC22: 120 | AD22: 120 | AE22: Assumed
A23: T017 | B23: ChengLong L2EV | C23: 181000 | G23: Battery | I23: Unconfirmed | J23: 22 | K23: DC | L23: 48 | O23: Keep ICE | R23: Keep ICE | W23: 0 | X23: 0 | Y23: 0 | Z23: 0 | AA23: 0 | AB23: No | AC23: 120 | AD23: 120 | AE23: Assumed
A24: T018 | B24: ChengLong L2EV | C24: 181000 | G24: Battery | I24: Unconfirmed | J24: 22 | K24: DC | L24: 48 | O24: Keep ICE | R24: Keep ICE | W24: 0 | X24: 0 | Y24: 0 | Z24: 0 | AA24: 0 | AB24: No | AC24: 120 | AD24: 120 | AE24: Assumed
... A106: T100 | B106: ChengLong L2EV | C106: 181000 | G106: Battery | I106: Unconfirmed | J106: 22 | K106: DC | L106: 48 | O106: Keep ICE | R106: Keep ICE | W106: 0 | X106: 0 | Y106: 0 | Z106: 0 | AA106: 0 | AB106: No | AC106: 120 | AD106: 120 | AE106: Assumed

Sheet Energy and charging
A2: 3. Enter prices and each plan's charging arrangement
A4: Amber inputs. Blank site work = unknown, not zero. Costs apply once per plan, not once per truck.
A6: Input / cost item | B6: Plan A | C6: Plan B | D6: Unit | E6: Scope / evidence
A7: Commercial diesel | B7: 2 | C7: 2 | D7: SGD/litre | E7: Inherited assumption; enter net fleet invoice
A8: Public diesel | B8: 3 | C8: 3 | D8: SGD/litre | E8: Inherited assumption; enter net public pump price
A9: Commercial diesel share | B9: 1 | C9: 1 | D9: litres share | E9: Commercial purchase share
A10: Depot electricity | B10: 0.3478 | C10: 0.3478 | D10: SGD/grid kWh | E10: Inherited assumption; not current commercial offer
A11: Public charging | B11: 0.85 | C11: 0.85 | D11: SGD/grid kWh | E11: Inherited assumption; verify truck access
A12: Public electricity share | B12: 0.2 | C12: 0.2 | D12: grid-kWh share | E12: Energy share, not visits share
A13: Charging-site arrangement | B13: Existing depot | C13: Existing depot | D13: site | E13: Existing depot / New rented site / Public only / Operator funded
A14: Site location | B14: Unspecified | C14: Unspecified | D14: region | E14: All Singapore areas considered; does not select a rent quote
A15: Charger type | B15: DC60 | C15: DC60 | D15: type | E15: DC60 / DC120 / AC22 / Other
A16: Installed chargers | B16: 1 | C16: 2 | D16: units | E16: Actual installed hardware, not EV count
A17: Usable truck plugs | B17: 2 | C17: 4 | D17: usable plugs | E17: Actual simultaneous truck positions; sharing still limited by site power
